Workbook

Sheet ÍNDICE
B2: Tabela de Preços Vivo (Índice)
B4: DOCUMENTO CONFIDENCIAL
B5: No pós pago a orientação é de sempre utilizarmos a tabela “Mais Vivo” nos precificadores, para nos mantermos atrativos frente a concorrência e em linha com as mídias cooperadas.
D7: Vigência a partir de | F7: 46280
B9: Diretoria | F9: Gerência
B10: Dir Marketing Consumer Electronics | F10: Gerência Pricing Estratégico
B11: Diretor Responsável | F11: Gerente Responsável
B12: Arnaud Jean Dusaintpere | F12: Eric Kikuti
B13: Documento Elaborado por | F13: Classificação do Documento
B14: Bruna Marques | F14: Sempre Confidencial
B16: ATENÇÃO
B17: As informações existentes neste documento são para conhecimento e uso confidencial dos destinatários abaixo, sendo seu sigilo protegido por lei e seu uso regulado por política interna específica da VIVO.
B20: TABELAS
B22: RESUMO DAS ALTERAÇÕES | F22: ELETRÔNICOS_LP_Conectados
B24: LISTA DE PLANOS | F24: ELETRÔNICOS_LP_Não Conectados
B26: LISTA DE PRODUTOS | F26: VITRINE
B28: SMARTPHONES e WATCHES CONECTADOS | F28: SMARTPHONES_Demo
B30: INFORMAÇÕES ADICIONAIS
F32: PVP aparelho NÃO inclui Chip, cujo valor é R$13
F34: Revendas utilizam o mesmo preço de lojas proprias.
F36: Preço referência 2x a 12x para pagamentos no Crédito a vista, débito, dinheiro e Vivo Pay.

Sheet ALTERAÇÕES
A1: RESUMO DE ALTERAÇÕES
A2: SMARTPHONES E WATCHES | C2: SMARTPHONES E WATCHES Renova | E2: ELETRÔNICOS_LP_Não Conectados | G2: ELETRÔNICOS_LP_Conectados | I2: ELETRÔNICOS_LP_Conectados RENOVA | K2: VITRINE | M2: SMARTPHONES_Demo
A3: {=IFERROR(_xlfn._xlws.SORT(_xlfn._xlws.FILTER(SMARTPHONES!E:E,SMARTPHONES!OL:OL=1)),"Sem alterações")} -> iPhone 15 256GB | C3: {=IFERROR(_xlfn._xlws.SORT(_xlfn._xlws.FILTER(SMARTPHONES!E:E,SMARTPHONES!OM:OM=1)),"Sem alterações")} -> Samsung Galaxy S26 FE 256GB | E3: {=IFERROR(_xlfn._xlws.SORT(_xlfn._xlws.FILTER('ELETRÔNICOS_LP_Não Conectados'!D:D,'ELETRÔNICOS_LP_Não Conectados'!AB:AB=1)),"Sem alterações")} -> Cabo Magnetico Lightning|C 1,2M I2GO | G3: {=IFERROR(_xlfn._xlws.SORT(_xlfn._xlws.FILTER(ELETRÔNICOS_LP_Conectados!E:E,ELETRÔNICOS_LP_Conectados!KX:KX=1)),"Sem alterações")} -> Samsung Galaxy Tab A11+ 5G 128GB | I3: {=IFERROR(_xlfn._xlws.SORT(_xlfn._xlws.FILTER(ELETRÔNICOS_LP_Conectados!E:E,ELETRÔNICOS_LP_Conectados!KY:KY=1)),"Sem alterações")} -> Sem alterações | K3: {=IFERROR(_xlfn._xlws.SORT(_xlfn._xlws.FILTER(VITRINE!D:D,VITRINE!AC:AC=1)),"Sem alterações")} -> Sem alterações | M3: {=IFERROR(_xlfn._xlws.SORT(_xlfn._xlws.FILTER(SMARTPHONES_Demo!D:D,SMARTPHONES_Demo!H:H=1)),"Sem alterações")} -> Sem alterações
A4: JOVI V70 5G 512GB | E4: Cabo Magnético USB-C/C 1,2M I2GO | G4: Samsung Galaxy Tab S10 FE 5G 128GB
A5: Moto G Max 5G 256GB | E5: Carregador Parede Universal 45W Ovvi
A6: Motorola Edge 70 512GB | E6: Console PS5 Slim Digital Com Astro Bot e Gran Turismo 7
A7: Oppo A6X 5G 256GB | E7: Console PS5 Slim Disk Com Astro Bot e Gran Turismo 7
A8: Samsung Galaxy A37 5G 256GB | E8: Controle sem fio DualSense™ Midnight Black
A9: Samsung Galaxy S26 Ultra 256GB | E9: Estojo P/ Acessórios I2GO
A10: Samsung Galaxy Z Fold 8 256GB | E10: Galaxy Buds 3 FE
E11: Kit Creator 5 em 1 I2GO
E12: Monitor Portátil Acer PM161Q 15.6 Pol
E13: Nintendo Switch 2 com Mario Kart World
E14: Nintendo Switch Oled
E15: Nintendo Switch Oled com Mario Bros Wonder
E16: Nintendo Switch V2 com Super Mario Bros Wonder
E17: Powerbank 20.000 MAH 12W I2GO
E18: Powerbank 5000 Pocket Lightning I2GO
E19: Powerbank Pocket 5.000 USB-C I2GO
E20: Powerbank 5000MAH Magsafe Slim Ovvi
E21: Robô Aspirador W90 WAP
E22: Samsung Galaxy Tab S10 FE Wi-Fi 128GB
... E31: Smart TV Samsung Vision AI QLED 4K QEF1 2025 50Pol

Sheet PLANOS
A1: PRODUTO | B1: TIPO DE PLANO | C1: NOME DO PLANO CLIENTE SISTEMA | D1: NOME DO BUNDLE (PLANOS VIVO TOTAL) | E1: SISTEMA | F1: GRUPAMENTO ATUAL | G1: COD SISTEMA | H1: COD SAP (USAR PARA VENDA MANUAL) | I1: NOME PLANO SAP (VENDA MANUAL) | J1: RENOVA COD SAP (VENDA MANUAL) | K1: RENOVA NOME PLANO SAP (VENDA MANUAL) | L1: GRUPAMENTO ANTERIOR | M1: OBSERVAÇÃO
A2: SMARTPHONE_SMARTWATCH | B2: Disponível para ALTA/MIGRAÇÃO | C2: VIVO CONTROLE 15GB VIII | D2: - | E2: NEXT | F2: CONTROLE ENTRADA | G2: 44640499 | H2: =_xlfn.XLOOKUP(F2,'AUXILIAR SAP'!E:E,'AUXILIAR SAP'!B:B) -> BC4 | I2: =_xlfn.XLOOKUP(F2,'AUXILIAR SAP'!E:E,'AUXILIAR SAP'!D:D) -> CONTROLE_ENT | J2: =IFERROR(_xlfn.XLOOKUP(F2,'AUXILIAR SAP'!J:J,'AUXILIAR SAP'!G:G),"-") -> BE4 | K2: =IFERROR(_xlfn.XLOOKUP(F2,'AUXILIAR SAP'!J:J,'AUXILIAR SAP'!I:I),"-") -> REN_CONTROLE_ENT | L2: CONTROLE ENTRADA | M2: Alteração de nomenclatura 26/03/26
A3: SMARTPHONE_SMARTWATCH | B3: Disponível para ALTA/MIGRAÇÃO | C3: VIVO CONTROLE 20GB IX | D3: - | E3: NEXT | F3: CONTROLE ALTO VALOR | G3: 44640509 | H3: =_xlfn.XLOOKUP(F3,'AUXILIAR SAP'!E:E,'AUXILIAR SAP'!B:B) -> CU6 | I3: =_xlfn.XLOOKUP(F3,'AUXILIAR SAP'!E:E,'AUXILIAR SAP'!D:D) -> CONTROLE_AV | J3: =IFERROR(_xlfn.XLOOKUP(F3,'AUXILIAR SAP'!J:J,'AUXILIAR SAP'!G:G),"-") -> CY2 | K3: =IFERROR(_xlfn.XLOOKUP(F3,'AUXILIAR SAP'!J:J,'AUXILIAR SAP'!I:I),"-") -> REN_CONTROLE_AV | L3: CONTROLE ALTO VALOR | M3: Alteração de nomenclatura 26/03/26
A4: SMARTPHONE_SMARTWATCH | B4: Disponível para ALTA/MIGRAÇÃO | C4: VIVO CONTROLE 20GB X | D4: - | E4: NEXT | F4: CONTROLE ALTO VALOR | G4: 44640529 | H4: =_xlfn.XLOOKUP(F4,'AUXILIAR SAP'!E:E,'AUXILIAR SAP'!B:B) -> CU6 | I4: =_xlfn.XLOOKUP(F4,'AUXILIAR SAP'!E:E,'AUXILIAR SAP'!D:D) -> CONTROLE_AV | J4: =IFERROR(_xlfn.XLOOKUP(F4,'AUXILIAR SAP'!J:J,'AUXILIAR SAP'!G:G),"-") -> CY2 | K4: =IFERROR(_xlfn.XLOOKUP(F4,'AUXILIAR SAP'!J:J,'AUXILIAR SAP'!I:I),"-") -> REN_CONTROLE_AV | L4: CONTROLE ALTO VALOR | M4: Alteração de nomenclatura 26/03/26
A5: SMARTPHONE_SMARTWATCH | B5: Disponível para ALTA/MIGRAÇÃO | C5: VIVO CONTROLE VANTAGENS 20GB | D5: - | E5: NEXT | F5: CONTROLE ALTO VALOR | G5: 44640549 | H5: =_xlfn.XLOOKUP(F5,'AUXILIAR SAP'!E:E,'AUXILIAR SAP'!B:B) -> CU6 | I5: =_xlfn.XLOOKUP(F5,'AUXILIAR SAP'!E:E,'AUXILIAR SAP'!D:D) -> CONTROLE_AV | J5: =IFERROR(_xlfn.XLOOKUP(F5,'AUXILIAR SAP'!J:J,'AUXILIAR SAP'!G:G),"-") -> CY2 | K5: =IFERROR(_xlfn.XLOOKUP(F5,'AUXILIAR SAP'!J:J,'AUXILIAR SAP'!I:I),"-") -> REN_CONTROLE_AV | L5: CONTROLE ALTO VALOR | M5: Alteração de nomenclatura 26/03/26
A6: SMARTPHONE_SMARTWATCH | B6: Disponível para ALTA/MIGRAÇÃO | C6: VIVO CONTROLE MÚSICA 20GB | D6: - | E6: NEXT | F6: CONTROLE ALTO VALOR | G6: 44640559 | H6: =_xlfn.XLOOKUP(F6,'AUXILIAR SAP'!E:E,'AUXILIAR SAP'!B:B) -> CU6 | I6: =_xlfn.XLOOKUP(F6,'AUXILIAR SAP'!E:E,'AUXILIAR SAP'!D:D) -> CONTROLE_AV | J6: =IFERROR(_xlfn.XLOOKUP(F6,'AUXILIAR SAP'!J:J,'AUXILIAR SAP'!G:G),"-") -> CY2 | K6: =IFERROR(_xlfn.XLOOKUP(F6,'AUXILIAR SAP'!J:J,'AUXILIAR SAP'!I:I),"-") -> REN_CONTROLE_AV | L6: CONTROLE ALTO VALOR | M6: Alteração de nomenclatura 26/03/26
A7: SMARTPHONE_SMARTWATCH | B7: Disponível para ALTA/MIGRAÇÃO | C7: VIVO CONTROLE 20GB PLN | D7: - | E7: NEXT | F7: CONTROLE ALTO VALOR | G7: 44640569 | H7: =_xlfn.XLOOKUP(F7,'AUXILIAR SAP'!E:E,'AUXILIAR SAP'!B:B) -> CU6 | I7: =_xlfn.XLOOKUP(F7,'AUXILIAR SAP'!E:E,'AUXILIAR SAP'!D:D) -> CONTROLE_AV | J7: =IFERROR(_xlfn.XLOOKUP(F7,'AUXILIAR SAP'!J:J,'AUXILIAR SAP'!G:G),"-") -> CY2 | K7: =IFERROR(_xlfn.XLOOKUP(F7,'AUXILIAR SAP'!J:J,'AUXILIAR SAP'!I:I),"-") -> REN_CONTROLE_AV | L7: CONTROLE ALTO VALOR | M7: Alteração de nomenclatura 26/03/26
A8: SMARTPHONE_SMARTWATCH | B8: Não disponível para ALTA/MIGRAÇÃO | C8: VIVO CONTROLE 9GB II | D8: - | E8: NEXT | F8: CONTROLE BTL | G8: 105008282 | H8: =_xlfn.XLOOKUP(F8,'AUXILIAR SAP'!E:E,'AUXILIAR SAP'!B:B) -> ZF4 | I8: =_xlfn.XLOOKUP(F8,'AUXILIAR SAP'!E:E,'AUXILIAR SAP'!D:D) -> CONTROLE_BTL | J8: =IFERROR(_xlfn.XLOOKUP(F8,'AUXILIAR SAP'!J:J,'AUXILIAR SAP'!G:G),"-") -> ZF7 | K8: =IFERROR(_xlfn.XLOOKUP(F8,'AUXILIAR SAP'!J:J,'AUXILIAR SAP'!I:I),"-") -> REN_CONTROLE_BTL | L8: PRÉ | M8: Alteração de nomenclatura 26/03/26
A9: SMARTPHONE_SMARTWATCH | B9: Não disponível para ALTA/MIGRAÇÃO | C9: VIVO CONTROLE 6GB II | D9: - | E9: NEXT | F9: CONTROLE BTL | G9: 483298854 | H9: =_xlfn.XLOOKUP(F9,'AUXILIAR SAP'!E:E,'AUXILIAR SAP'!B:B) -> ZF4 | I9: =_xlfn.XLOOKUP(F9,'AUXILIAR SAP'!E:E,'AUXILIAR SAP'!D:D) -> CONTROLE_BTL | J9: =IFERROR(_xlfn.XLOOKUP(F9,'AUXILIAR SAP'!J:J,'AUXILIAR SAP'!G:G),"-") -> ZF7 | K9: =IFERROR(_xlfn.XLOOKUP(F9,'AUXILIAR SAP'!J:J,'AUXILIAR SAP'!I:I),"-") -> REN_CONTROLE_BTL | L9: PRÉ | M9: Alteração de nome do Grupamento 28/08
A10: SMARTPHONE_SMARTWATCH | B10: Não disponível para ALTA/MIGRAÇÃO | C10: VIVO CONTROLE 7GB III | D10: - | E10: NEXT | F10: CONTROLE BTL | G10: 483298914 | H10: =_xlfn.XLOOKUP(F10,'AUXILIAR SAP'!E:E,'AUXILIAR SAP'!B:B) -> ZF4 | I10: =_xlfn.XLOOKUP(F10,'AUXILIAR SAP'!E:E,'AUXILIAR SAP'!D:D) -> CONTROLE_BTL | J10: =IFERROR(_xlfn.XLOOKUP(F10,'AUXILIAR SAP'!J:J,'AUXILIAR SAP'!G:G),"-") -> ZF7 | K10: =IFERROR(_xlfn.XLOOKUP(F10,'AUXILIAR SAP'!J:J,'AUXILIAR SAP'!I:I),"-") -> REN_CONTROLE_BTL | L10: PRÉ | M10: Alteração de nome do Grupamento 28/08
A11: SMARTPHONE_SMARTWATCH | B11: Não disponível para ALTA/MIGRAÇÃO | C11: VIVO CONTROLE 6GB V | D11: - | E11: NEXT | F11: CONTROLE BTL | G11: 483298864 | H11: =_xlfn.XLOOKUP(F11,'AUXILIAR SAP'!E:E,'AUXILIAR SAP'!B:B) -> ZF4 | I11: =_xlfn.XLOOKUP(F11,'AUXILIAR SAP'!E:E,'AUXILIAR SAP'!D:D) -> CONTROLE_BTL | J11: =IFERROR(_xlfn.XLOOKUP(F11,'AUXILIAR SAP'!J:J,'AUXILIAR SAP'!G:G),"-") -> ZF7 | K11: =IFERROR(_xlfn.XLOOKUP(F11,'AUXILIAR SAP'!J:J,'AUXILIAR SAP'!I:I),"-") -> REN_CONTROLE_BTL | L11: PRÉ | M11: Alteração de nome do Grupamento 28/08
A12: SMARTPHONE_SMARTWATCH | B12: Não disponível para ALTA/MIGRAÇÃO | C12: VIVO CONTROLE BÁSICO 13GB | D12: - | E12: NEXT | F12: CONTROLE BTL | G12: 484085673 | H12: =_xlfn.XLOOKUP(F12,'AUXILIAR SAP'!E:E,'AUXILIAR SAP'!B:B) -> ZF4 | I12: =_xlfn.XLOOKUP(F12,'AUXILIAR SAP'!E:E,'AUXILIAR SAP'!D:D) -> CONTROLE_BTL | J12: =IFERROR(_xlfn.XLOOKUP(F12,'AUXILIAR SAP'!J:J,'AUXILIAR SAP'!G:G),"-") -> ZF7 | K12: =IFERROR(_xlfn.XLOOKUP(F12,'AUXILIAR SAP'!J:J,'AUXILIAR SAP'!I:I),"-") -> REN_CONTROLE_BTL | L12: PRÉ | M12: Alteração de nomenclatura 26/03/26
A13: SMARTPHONE_SMARTWATCH | B13: Não disponível para ALTA/MIGRAÇÃO | C13: VIVO CONTROLE 10GB_V | D13: - | E13: NEXT | F13: CONTROLE ALTO VALOR | G13: 104564912 | H13: =_xlfn.XLOOKUP(F13,'AUXILIAR SAP'!E:E,'AUXILIAR SAP'!B:B) -> CU6 | I13: =_xlfn.XLOOKUP(F13,'AUXILIAR SAP'!E:E,'AUXILIAR SAP'!D:D) -> CONTROLE_AV | J13: =IFERROR(_xlfn.XLOOKUP(F13,'AUXILIAR SAP'!J:J,'AUXILIAR SAP'!G:G),"-") -> CY2 | K13: =IFERROR(_xlfn.XLOOKUP(F13,'AUXILIAR SAP'!J:J,'AUXILIAR SAP'!I:I),"-") -> REN_CONTROLE_AV | L13: CONTROLE ALTO VALOR | M13: Alteração de nomenclatura 26/03/26
... A19: SMARTPHONE_SMARTWATCH | B19: Não disponível para ALTA/MIGRAÇÃO | C19: VIVO CONTROLE 8GB | D19: - | E19: NEXT | F19: CONTROLE ENTRADA | G19: 435224237 | H19: =_xlfn.XLOOKUP(F19,'AUXILIAR SAP'!E:E,'AUXILIAR SAP'!B:B) -> BC4 | I19: =_xlfn.XLOOKUP(F19,'AUXILIAR SAP'!E:E,'AUXILIAR SAP'!D:D) -> CONTROLE_ENT | J19: =IFERROR(_xlfn.XLOOKUP(F19,'AUXILIAR SAP'!J:J,'AUXILIAR SAP'!G:G),"-") -> BE4 | K19: =IFERROR(_xlfn.XLOOKUP(F19,'AUXILIAR SAP'!J:J,'AUXILIAR SAP'!I:I),"-") -> REN_CONTROLE_ENT | L19: CONTROLE ENTRADA | M19: Alteração de grupamento
A20: SMARTPHONE_SMARTWATCH | B20: Não disponível para ALTA/MIGRAÇÃO | C20: VIVO CTRL NOVO 14GB | D20: - | E20: NEXT | F20: CONTROLE ALTO VALOR | G20: 104564922 | H20: =_xlfn.XLOOKUP(F20,'AUXILIAR SAP'!E:E,'AUXILIAR SAP'!B:B) -> CU6 | I20: =_xlfn.XLOOKUP(F20,'AUXILIAR SAP'!E:E,'AUXILIAR SAP'!D:D) -> CONTROLE_AV | J20: =IFERROR(_xlfn.XLOOKUP(F20,'AUXILIAR SAP'!J:J,'AUXILIAR SAP'!G:G),"-") -> CY2 | K20: =IFERROR(_xlfn.XLOOKUP(F20,'AUXILIAR SAP'!J:J,'AUXILIAR SAP'!I:I),"-") -> REN_CONTROLE_AV | L20: CONTROLE ALTO VALOR
A21: SMARTPHONE_SMARTWATCH | B21: Não disponível para ALTA/MIGRAÇÃO | C21: VIVO CONTROLE 6GB VIII | D21: - | E21: NEXT | F21: CONTROLE BTL | G21: 483298904 | H21: =_xlfn.XLOOKUP(F21,'AUXILIAR SAP'!E:E,'AUXILIAR SAP'!B:B) -> ZF4 | I21: =_xlfn.XLOOKUP(F21,'AUXILIAR SAP'!E:E,'AUXILIAR SAP'!D:D) -> CONTROLE_BTL | J21: =IFERROR(_xlfn.XLOOKUP(F21,'AUXILIAR SAP'!J:J,'AUXILIAR SAP'!G:G),"-") -> ZF7 | K21: =IFERROR(_xlfn.XLOOKUP(F21,'AUXILIAR SAP'!J:J,'AUXILIAR SAP'!I:I),"-") -> REN_CONTROLE_BTL | L21: PRÉ | M21: Alteração de nome do Grupamento 28/08
A22: SMARTPHONE_SMARTWATCH | B22: Não disponível para ALTA/MIGRAÇÃO | C22: VIVO CONTROLE 14GB I | D22: - | E22: NEXT | F22: CONTROLE ALTO VALOR | G22: 104564932 | H22: =_xlfn.XLOOKUP(F22,'AUXILIAR SAP'!E:E,'AUXILIAR SAP'!B:B) -> CU6 | I22: =_xlfn.XLOOKUP(F22,'AUXILIAR SAP'!E:E,'AUXILIAR SAP'!D:D) -> CONTROLE_AV | J22: =IFERROR(_xlfn.XLOOKUP(F22,'AUXILIAR SAP'!J:J,'AUXILIAR SAP'!G:G),"-") -> CY2 | K22: =IFERROR(_xlfn.XLOOKUP(F22,'AUXILIAR SAP'!J:J,'AUXILIAR SAP'!I:I),"-") -> REN_CONTROLE_AV | L22: CONTROLE ALTO VALOR
A23: SMARTPHONE_SMARTWATCH | B23: Não disponível para ALTA/MIGRAÇÃO | C23: VIVO CONTROLE 7GB V | D23: - | E23: NEXT | F23: CONTROLE BTL | G23: 434823532 | H23: =_xlfn.XLOOKUP(F23,'AUXILIAR SAP'!E:E,'AUXILIAR SAP'!B:B) -> ZF4 | I23: =_xlfn.XLOOKUP(F23,'AUXILIAR SAP'!E:E,'AUXILIAR SAP'!D:D) -> CONTROLE_BTL | J23: =IFERROR(_xlfn.XLOOKUP(F23,'AUXILIAR SAP'!J:J,'AUXILIAR SAP'!G:G),"-") -> ZF7 | K23: =IFERROR(_xlfn.XLOOKUP(F23,'AUXILIAR SAP'!J:J,'AUXILIAR SAP'!I:I),"-") -> REN_CONTROLE_BTL | L23: PRÉ | M23: Alteração de nome do Grupamento 28/08
A24: SMARTPHONE_SMARTWATCH | B24: Não disponível para ALTA/MIGRAÇÃO | C24: VIVO CONTROLE BÁSICO 15GB | D24: - | E24: NEXT | F24: CONTROLE BTL | G24: 484085683 | H24: =_xlfn.XLOOKUP(F24,'AUXILIAR SAP'!E:E,'AUXILIAR SAP'!B:B) -> ZF4 | I24: =_xlfn.XLOOKUP(F24,'AUXILIAR SAP'!E:E,'AUXILIAR SAP'!D:D) -> CONTROLE_BTL | J24: =IFERROR(_xlfn.XLOOKUP(F24,'AUXILIAR SAP'!J:J,'AUXILIAR SAP'!G:G),"-") -> ZF7 | K24: =IFERROR(_xlfn.XLOOKUP(F24,'AUXILIAR SAP'!J:J,'AUXILIAR SAP'!I:I),"-") -> REN_CONTROLE_BTL | L24: PRÉ | M24: Alteração de nomenclatura 26/03/26
A25: SMARTPHONE_SMARTWATCH | B25: Não disponível para ALTA/MIGRAÇÃO | C25: VIVO CONTROLE 9GB - 25MIN_ | D25: - | E25: NEXT | F25: CONTROLE ENTRADA | G25: 434823522 | H25: =_xlfn.XLOOKUP(F25,'AUXILIAR SAP'!E:E,'AUXILIAR SAP'!B:B) -> BC4 | I25: =_xlfn.XLOOKUP(F25,'AUXILIAR SAP'!E:E,'AUXILIAR SAP'!D:D) -> CONTROLE_ENT | J25: =IFERROR(_xlfn.XLOOKUP(F25,'AUXILIAR SAP'!J:J,'AUXILIAR SAP'!G:G),"-") -> BE4 | K25: =IFERROR(_xlfn.XLOOKUP(F25,'AUXILIAR SAP'!J:J,'AUXILIAR SAP'!I:I),"-") -> REN_CONTROLE_ENT | L25: CONTROLE ENTRADA | M25: Alteração de grupamento
A26: SMARTPHONE_SMARTWATCH | B26: Não disponível para ALTA/MIGRAÇÃO | C26: VIVO CONTROLE 14GB XI | D26: - | E26: NEXT | F26: CONTROLE ENTRADA | G26: 104285068 | H26: =_xlfn.XLOOKUP(F26,'AUXILIAR SAP'!E:E,'AUXILIAR SAP'!B:B) -> BC4 | I26: =_xlfn.XLOOKUP(F26,'AUXILIAR SAP'!E:E,'AUXILIAR SAP'!D:D) -> CONTROLE_ENT | J26: =IFERROR(_xlfn.XLOOKUP(F26,'AUXILIAR SAP'!J:J,'AUXILIAR SAP'!G:G),"-") -> BE4 | K26: =IFERROR(_xlfn.XLOOKUP(F26,'AUXILIAR SAP'!J:J,'AUXILIAR SAP'!I:I),"-") -> REN_CONTROLE_ENT | L26: CONTROLE ENTRADA | M26: Alteração de nomenclatura 26/03/26
A27: SMARTPHONE_SMARTWATCH | B27: Não disponível para ALTA/MIGRAÇÃO | C27: VIVO CONTROLE 7GB VII | D27: - | E27: NEXT | F27: CONTROLE BTL | G27: 434823542 | H27: =_xlfn.XLOOKUP(F27,'AUXILIAR SAP'!E:E,'AUXILIAR SAP'!B:B) -> ZF4 | I27: =_xlfn.XLOOKUP(F27,'AUXILIAR SAP'!E:E,'AUXILIAR SAP'!D:D) -> CONTROLE_BTL | J27: =IFERROR(_xlfn.XLOOKUP(F27,'AUXILIAR SAP'!J:J,'AUXILIAR SAP'!G:G),"-") -> ZF7 | K27: =IFERROR(_xlfn.XLOOKUP(F27,'AUXILIAR SAP'!J:J,'AUXILIAR SAP'!I:I),"-") -> REN_CONTROLE_BTL | L27: PRÉ | M27: Alteração de nome do Grupamento 28/08
A28: SMARTPHONE_SMARTWATCH | B28: Não disponível para ALTA/MIGRAÇÃO | C28: VIVO CONTROLE 7GB VI | D28: - | E28: NEXT | F28: CONTROLE BTL | G28: 434823552 | H28: =_xlfn.XLOOKUP(F28,'AUXILIAR SAP'!E:E,'AUXILIAR SAP'!B:B) -> ZF4 | I28: =_xlfn.XLOOKUP(F28,'AUXILIAR SAP'!E:E,'AUXILIAR SAP'!D:D) -> CONTROLE_BTL | J28: =IFERROR(_xlfn.XLOOKUP(F28,'AUXILIAR SAP'!J:J,'AUXILIAR SAP'!G:G),"-") -> ZF7 | K28: =IFERROR(_xlfn.XLOOKUP(F28,'AUXILIAR SAP'!J:J,'AUXILIAR SAP'!I:I),"-") -> REN_CONTROLE_BTL | L28: PRÉ | M28: Alteração de nome do Grupamento 28/08
A29: SMARTPHONE_SMARTWATCH | B29: Não disponível para ALTA/MIGRAÇÃO | C29: VIVO CONTROLE 10GB VII | D29: - | E29: NEXT | F29: CONTROLE ALTO VALOR | G29: 104285088 | H29: =_xlfn.XLOOKUP(F29,'AUXILIAR SAP'!E:E,'AUXILIAR SAP'!B:B) -> CU6 | I29: =_xlfn.XLOOKUP(F29,'AUXILIAR SAP'!E:E,'AUXILIAR SAP'!D:D) -> CONTROLE_AV | J29: =IFERROR(_xlfn.XLOOKUP(F29,'AUXILIAR SAP'!J:J,'AUXILIAR SAP'!G:G),"-") -> CY2 | K29: =IFERROR(_xlfn.XLOOKUP(F29,'AUXILIAR SAP'!J:J,'AUXILIAR SAP'!I:I),"-") -> REN_CONTROLE_AV | L29: CONTROLE ALTO VALOR | M29: Alteração de grupamento
A30: SMARTPHONE_SMARTWATCH | B30: Não disponível para ALTA/MIGRAÇÃO | C30: VIVO CONTROLE 14GB IV | D30: - | E30: NEXT | F30: CONTROLE ALTO VALOR | G30: 104285098 | H30: =_xlfn.XLOOKUP(F30,'AUXILIAR SAP'!E:E,'AUXILIAR SAP'!B:B) -> CU6 | I30: =_xlfn.XLOOKUP(F30,'AUXILIAR SAP'!E:E,'AUXILIAR SAP'!D:D) -> CONTROLE_AV | J30: =IFERROR(_xlfn.XLOOKUP(F30,'AUXILIAR SAP'!J:J,'AUXILIAR SAP'!G:G),"-") -> CY2 | K30: =IFERROR(_xlfn.XLOOKUP(F30,'AUXILIAR SAP'!J:J,'AUXILIAR SAP'!I:I),"-") -> REN_CONTROLE_AV | L30: CONTROLE ALTO VALOR
A31: SMARTPHONE_SMARTWATCH | B31: Disponível para ALTA | C31: VIVO CONTROLE 16GB X | D31: - | E31: NEXT | F31: CONTROLE ALTO VALOR | G31: 104285078 | H31: =_xlfn.XLOOKUP(F31,'AUXILIAR SAP'!E:E,'AUXILIAR SAP'!B:B) -> CU6 | I31: =_xlfn.XLOOKUP(F31,'AUXILIAR SAP'!E:E,'AUXILIAR SAP'!D:D) -> CONTROLE_AV | J31: =IFERROR(_xlfn.XLOOKUP(F31,'AUXILIAR SAP'!J:J,'AUXILIAR SAP'!G:G),"-") -> CY2 | K31: =IFERROR(_xlfn.XLOOKUP(F31,'AUXILIAR SAP'!J:J,'AUXILIAR SAP'!I:I),"-") -> REN_CONTROLE_AV | L31: CONTROLE ALTO VALOR | M31: Alteração de nomenclatura 26/03/26
A32: SMARTPHONE_SMARTWATCH | B32: Não disponível para ALTA/MIGRAÇÃO | C32: VIVO CONTROLE 10GB VIII | D32: - | E32: NEXT | F32: CONTROLE ALTO VALOR | G32: 435224247 | H32: =_xlfn.XLOOKUP(F32,'AUXILIAR SAP'!E:E,'AUXILIAR SAP'!B:B) -> CU6 | I32: =_xlfn.XLOOKUP(F32,'AUXILIAR SAP'!E:E,'AUXILIAR SAP'!D:D) -> CONTROLE_AV | J32: =IFERROR(_xlfn.XLOOKUP(F32,'AUXILIAR SAP'!J:J,'AUXILIAR SAP'!G:G),"-") -> CY2 | K32: =IFERROR(_xlfn.XLOOKUP(F32,'AUXILIAR SAP'!J:J,'AUXILIAR SAP'!I:I),"-") -> REN_CONTROLE_AV | L32: CONTROLE ALTO VALOR | M32: Alteração de grupamento
A33: SMARTPHONE_SMARTWATCH | B33: Não disponível para ALTA/MIGRAÇÃO | C33: VIVO CONTROLE 10GB III | D33: - | E33: NEXT | F33: CONTROLE BTL | G33: 105008302 | H33: =_xlfn.XLOOKUP(F33,'AUXILIAR SAP'!E:E,'AUXILIAR SAP'!B:B) -> ZF4 | I33: =_xlfn.XLOOKUP(F33,'AUXILIAR SAP'!E:E,'AUXILIAR SAP'!D:D) -> CONTROLE_BTL | J33: =IFERROR(_xlfn.XLOOKUP(F33,'AUXILIAR SAP'!J:J,'AUXILIAR SAP'!G:G),"-") -> ZF7 | K33: =IFERROR(_xlfn.XLOOKUP(F33,'AUXILIAR SAP'!J:J,'AUXILIAR SAP'!I:I),"-") -> REN_CONTROLE_BTL | L33: PRÉ | M33: Alteração de nomenclatura 26/03/26
A34: SMARTPHONE_SMARTWATCH | B34: Disponível para ALTA/MIGRAÇÃO | C34: TITULAR VIVO POS ESSENCIAL 40GB PLN | D34: - | E34: NEXT | F34: PÓS INDIVIDUAL | G34: 104375982 | H34: =_xlfn.XLOOKUP(F34,'AUXILIAR SAP'!E:E,'AUXILIAR SAP'!B:B) -> ZF2 | I34: =_xlfn.XLOOKUP(F34,'AUXILIAR SAP'!E:E,'AUXILIAR SAP'!D:D) -> PÓS_IND | J34: =IFERROR(_xlfn.XLOOKUP(F34,'AUXILIAR SAP'!J:J,'AUXILIAR SAP'!G:G),"-") -> ZF5 | K34: =IFERROR(_xlfn.XLOOKUP(F34,'AUXILIAR SAP'!J:J,'AUXILIAR SAP'!I:I),"-") -> REN_PÓS_IND | L34: PÓS INDIVIDUAL | M34: Alteração do Plano
A35: SMARTPHONE_SMARTWATCH | B35: Não disponível para ALTA/MIGRAÇÃO | C35: TITULAR VIVO PÓS 35GB II PLN | D35: - | E35: NEXT | F35: PÓS INDIVIDUAL | G35: 104376112 | H35: =_xlfn.XLOOKUP(F35,'AUXILIAR SAP'!E:E,'AUXILIAR SAP'!B:B) -> ZF2 | I35: =_xlfn.XLOOKUP(F35,'AUXILIAR SAP'!E:E,'AUXILIAR SAP'!D:D) -> PÓS_IND | J35: =IFERROR(_xlfn.XLOOKUP(F35,'AUXILIAR SAP'!J:J,'AUXILIAR SAP'!G:G),"-") -> ZF5 | K35: =IFERROR(_xlfn.XLOOKUP(F35,'AUXILIAR SAP'!J:J,'AUXILIAR SAP'!I:I),"-") -> REN_PÓS_IND | L35: PÓS INDIVIDUAL | M35: Alteração de nomenclatura 26/03/26
A36: SMARTPHONE_SMARTWATCH | B36: Não disponível para ALTA/MIGRAÇÃO | C36: TITULAR VIVO PÓS_40GB | D36: - | E36: NEXT | F36: PÓS INDIVIDUAL | G36: 104376172 | H36: =_xlfn.XLOOKUP(F36,'AUXILIAR SAP'!E:E,'AUXILIAR SAP'!B:B) -> ZF2 | I36: =_xlfn.XLOOKUP(F36,'AUXILIAR SAP'!E:E,'AUXILIAR SAP'!D:D) -> PÓS_IND | J36: =IFERROR(_xlfn.XLOOKUP(F36,'AUXILIAR SAP'!J:J,'AUXILIAR SAP'!G:G),"-") -> ZF5 | K36: =IFERROR(_xlfn.XLOOKUP(F36,'AUXILIAR SAP'!J:J,'AUXILIAR SAP'!I:I),"-") -> REN_PÓS_IND | L36: PÓS INDIVIDUAL | M36: Alteração de nomenclatura 26/03/26
A37: SMARTPHONE_SMARTWATCH | B37: Disponível para ALTA/MIGRAÇÃO | C37: TITULAR VIVO PÓS 35GB PLN | D37: - | E37: NEXT | F37: PÓS INDIVIDUAL | G37: 104376022 | H37: =_xlfn.XLOOKUP(F37,'AUXILIAR SAP'!E:E,'AUXILIAR SAP'!B:B) -> ZF2 | I37: =_xlfn.XLOOKUP(F37,'AUXILIAR SAP'!E:E,'AUXILIAR SAP'!D:D) -> PÓS_IND | J37: =IFERROR(_xlfn.XLOOKUP(F37,'AUXILIAR SAP'!J:J,'AUXILIAR SAP'!G:G),"-") -> ZF5 | K37: =IFERROR(_xlfn.XLOOKUP(F37,'AUXILIAR SAP'!J:J,'AUXILIAR SAP'!I:I),"-") -> REN_PÓS_IND | L37: PÓS INDIVIDUAL | M37: Alteração de nomenclatura 26/03/26
A38: SMARTPHONE_SMARTWATCH | B38: Não disponível para ALTA/MIGRAÇÃO | C38: TITULAR VIVO PÓS 35GB+ | D38: - | E38: NEXT | F38: PÓS INDIVIDUAL | G38: 104330938 | H38: =_xlfn.XLOOKUP(F38,'AUXILIAR SAP'!E:E,'AUXILIAR SAP'!B:B) -> ZF2 | I38: =_xlfn.XLOOKUP(F38,'AUXILIAR SAP'!E:E,'AUXILIAR SAP'!D:D) -> PÓS_IND | J38: =IFERROR(_xlfn.XLOOKUP(F38,'AUXILIAR SAP'!J:J,'AUXILIAR SAP'!G:G),"-") -> ZF5 | K38: =IFERROR(_xlfn.XLOOKUP(F38,'AUXILIAR SAP'!J:J,'AUXILIAR SAP'!I:I),"-") -> REN_PÓS_IND | L38: PÓS INDIVIDUAL | M38: Alteração de nomenclatura 26/03/26
A39: SMARTPHONE_SMARTWATCH | B39: Não disponível para ALTA/MIGRAÇÃO | C39: TITULAR VIVO PÓS 60GB | D39: - | E39: NEXT | F39: PÓS INDIVIDUAL | G39: 104376212 | H39: =_xlfn.XLOOKUP(F39,'AUXILIAR SAP'!E:E,'AUXILIAR SAP'!B:B) -> ZF2 | I39: =_xlfn.XLOOKUP(F39,'AUXILIAR SAP'!E:E,'AUXILIAR SAP'!D:D) -> PÓS_IND | J39: =IFERROR(_xlfn.XLOOKUP(F39,'AUXILIAR SAP'!J:J,'AUXILIAR SAP'!G:G),"-") -> ZF5 | K39: =IFERROR(_xlfn.XLOOKUP(F39,'AUXILIAR SAP'!J:J,'AUXILIAR SAP'!I:I),"-") -> REN_PÓS_IND | L39: PÓS INDIVIDUAL | M39: Alteração de nomenclatura 26/03/26
A40: SMARTPHONE_SMARTWATCH | B40: Disponível para ALTA/MIGRAÇÃO | C40: TITULAR VIVO POS TRAVEL 60GB PLN | D40: - | E40: NEXT | F40: PÓS INDIVIDUAL | G40: 104376062 | H40: =_xlfn.XLOOKUP(F40,'AUXILIAR SAP'!E:E,'AUXILIAR SAP'!B:B) -> ZF2 | I40: =_xlfn.XLOOKUP(F40,'AUXILIAR SAP'!E:E,'AUXILIAR SAP'!D:D) -> PÓS_IND | J40: =IFERROR(_xlfn.XLOOKUP(F40,'AUXILIAR SAP'!J:J,'AUXILIAR SAP'!G:G),"-") -> ZF5 | K40: =IFERROR(_xlfn.XLOOKUP(F40,'AUXILIAR SAP'!J:J,'AUXILIAR SAP'!I:I),"-") -> REN_PÓS_IND | L40: PÓS INDIVIDUAL | M40: Alteração do Plano 22/08
A41: SMARTPHONE_SMARTWATCH | B41: Não disponível para ALTA/MIGRAÇÃO | C41: TITULAR VIVO PÓS 60GB PLN | D41: - | E41: NEXT | F41: PÓS INDIVIDUAL | G41: 104376192 | H41: =_xlfn.XLOOKUP(F41,'AUXILIAR SAP'!E:E,'AUXILIAR SAP'!B:B) -> ZF2 | I41: =_xlfn.XLOOKUP(F41,'AUXILIAR SAP'!E:E,'AUXILIAR SAP'!D:D) -> PÓS_IND | J41: =IFERROR(_xlfn.XLOOKUP(F41,'AUXILIAR SAP'!J:J,'AUXILIAR SAP'!G:G),"-") -> ZF5 | K41: =IFERROR(_xlfn.XLOOKUP(F41,'AUXILIAR SAP'!J:J,'AUXILIAR SAP'!I:I),"-") -> REN_PÓS_IND | L41: PÓS INDIVIDUAL | M41: Alteração de nomenclatura 26/03/26
A42: SMARTPHONE_SMARTWATCH | B42: Não disponível para ALTA/MIGRAÇÃO | C42: TITULAR VIVO FAMÍLIA 105GB I | D42: - | E42: NEXT | F42: FAMILIA 3 | G42: 483901419 | H42: =_xlfn.XLOOKUP(F42,'AUXILIAR SAP'!E:E,'AUXILIAR SAP'!B:B) -> CU9 | I42: =_xlfn.XLOOKUP(F42,'AUXILIAR SAP'!E:E,'AUXILIAR SAP'!D:D) -> FAM_3 | J42: =IFERROR(_xlfn.XLOOKUP(F42,'AUXILIAR SAP'!J:J,'AUXILIAR SAP'!G:G),"-") -> CY5 | K42: =IFERROR(_xlfn.XLOOKUP(F42,'AUXILIAR SAP'!J:J,'AUXILIAR SAP'!I:I),"-") -> REN_FAM_3 | L42: FAMILIA 2 | M42: Alteração de nomenclatura 26/03/26
... A53: SMARTPHONE_SMARTWATCH | B53: Disponível para ALTA/MIGRAÇÃO | C53: TITULAR VIVO FAMÍLIA 205GB I PLN | D53: - | E53: NEXT | F53: FAMILIA 4/5 | G53: 104564642 | H53: =_xlfn.XLOOKUP(F53,'AUXILIAR SAP'!E:E,'AUXILIAR SAP'!B:B) -> CV2 | I53: =_xlfn.XLOOKUP(F53,'AUXILIAR SAP'!E:E,'AUXILIAR SAP'!D:D) -> FAM_4/5 | J53: =IFERROR(_xlfn.XLOOKUP(F53,'AUXILIAR SAP'!J:J,'AUXILIAR SAP'!G:G),"-") -> CY7 | K53: =IFERROR(_xlfn.XLOOKUP(F53,'AUXILIAR SAP'!J:J,'AUXILIAR SAP'!I:I),"-") -> REN_FAM_4/5 | L53: FAMILIA 4 | M53: Alteração de nomenclatura 26/03/26
A54: SMARTPHONE_SMARTWATCH | B54: Disponível para ALTA/MIGRAÇÃO | C54: TITULAR VIVO V PLN. | D54: - | E54: NEXT | F54: VIVO V | G54: 104564692 | H54: =_xlfn.XLOOKUP(F54,'AUXILIAR SAP'!E:E,'AUXILIAR SAP'!B:B) -> 28Y | I54: =_xlfn.XLOOKUP(F54,'AUXILIAR SAP'!E:E,'AUXILIAR SAP'!D:D) -> VIVO_V | J54: =IFERROR(_xlfn.XLOOKUP(F54,'AUXILIAR SAP'!J:J,'AUXILIAR SAP'!G:G),"-") -> 08Y | K54: =IFERROR(_xlfn.XLOOKUP(F54,'AUXILIAR SAP'!J:J,'AUXILIAR SAP'!I:I),"-") -> REN_VIVO_V | L54: VIVO V
A55: SMARTPHONE_SMARTWATCH | B55: Não disponível para ALTA/MIGRAÇÃO | C55: LINHA ADICIONAL VIVO FAMÍLIA 105GB I | D55: - | E55: NEXT | F55: CONTROLE ALTO VALOR | G55: 483907419 | H55: =_xlfn.XLOOKUP(F55,'AUXILIAR SAP'!E:E,'AUXILIAR SAP'!B:B) -> CU6 | I55: =_xlfn.XLOOKUP(F55,'AUXILIAR SAP'!E:E,'AUXILIAR SAP'!D:D) -> CONTROLE_AV | J55: =IFERROR(_xlfn.XLOOKUP(F55,'AUXILIAR SAP'!J:J,'AUXILIAR SAP'!G:G),"-") -> CY2 | K55: =IFERROR(_xlfn.XLOOKUP(F55,'AUXILIAR SAP'!J:J,'AUXILIAR SAP'!I:I),"-") -> REN_CONTROLE_AV | L55: CONTROLE ALTO VALOR | M55: Alteração de nomenclatura 26/03/26
...

Sheet AUXILIAR SAP
B2: Tabela Regular | G2: Tabela Renova
B3: COD SAP (USAR PARA VENDA MANUAL) | C3: NOME PLANO SAP (válido até 20/08/2025) | D3: NOME PLANO SAP (válido a partir de 21/08/2025) | E3: GRUPO TABELA DE PREÇOS (a partir de 28/08/2025) | G3: COD SAP RENOVA (USAR PARA VENDA MANUAL) | H3: NOME PLANO SAP (válido até 20/08/2025) | I3: NOME PLANO SAP (válido a partir de 21/08/2025) | J3: GRUPO TABELA DE PREÇOS (a partir de 28/08/2025)
B4: BC4 | C4: CONTROLE_ENT | D4: CONTROLE_ENT | E4: CONTROLE ENTRADA | G4: BE4 | H4: REN_CONTROLE_ENT | I4: REN_CONTROLE_ENT | J4: CONTROLE ENTRADA
B5: CU6 | C5: CONTROLE_AV | D5: CONTROLE_AV | E5: CONTROLE ALTO VALOR | G5: CY2 | H5: REN_CONTROLE_AV | I5: REN_CONTROLE_AV | J5: CONTROLE ALTO VALOR
B6: ZF2 | C6: PÓS_IND | D6: PÓS_IND | E6: PÓS INDIVIDUAL | G6: ZF5 | H6: REN_PÓS_IND | I6: REN_PÓS_IND | J6: PÓS INDIVIDUAL
B7: ZF3 | C7: FAM_1 | D7: FAM_2 | E7: FAMILIA 2 | G7: ZF6 | H7: REN_VIVO_TOT_IND | I7: REN_FAM_2 | J7: FAMILIA 2
B8: CU9 | C8: FAM_2 | D8: FAM_3 | E8: FAMILIA 3 | G8: CY5 | H8: REN_FAM_ENTRADA | I8: REN_FAM_3 | J8: FAMILIA 3
B9: CV2 | C9: FAM_3 | D9: FAM_4/5 | E9: FAMILIA 4/5 | G9: CY7 | H9: REN_FAM_ALTO_VALOR | I9: REN_FAM_4/5 | J9: FAMILIA 4/5
B10: ZF4 | C10: FAM_4 | D10: CONTROLE_BTL | E10: CONTROLE BTL | G10: ZF7 | H10: REN_VIVO_TOT_AV | I10: REN_CONTROLE_BTL | J10: CONTROLE BTL
B11: 28Y | C11: VIVO_V | D11: VIVO_V | E11: VIVO V | G11: 08Y | H11: REN_VIVO_V | I11: REN_VIVO_V | J11: VIVO V
B12: PPP | C12: PRE | D12: PRE | E12: PRÉ
B13: KAU | C13: MULTIVIVO | D13: MULTIVIVO | E13: MULTIVIVO
B14: YAQ | C14: VIM_8GB | D14: VIM_8GB | E14: VIM 8GB
B15: YAR | C15: VIM_14GB | D15: VIM_14GB | E15: VIM 14GB
B16: YAS | C16: VIM_20GB | D16: VIM_20GB | E16: VIM 20GB
B17: 85W | C17: VIM_40GB | D17: VIM_40GB | E17: VIM 40GB
B18: ZE5 | C18: VIM_100GB | D18: VIM_100GB | E18: VIM 100GB
B19: F10 | C19: FIXO_ILIMITADO | D19: FIXO_ILIMITADO | E19: Vivo Fixo Ilimitado
B20: F12 | C20: FIXO_ILIMITADO_TOTAL | D20: FIXO_ILIMITADO_TOTAL | E20: Vivo Fixo Ilimitado Total
B21: UYV | C21: VITRINE | D21: VITRINE | E21: -
B22: CHA | C22: CHIP_AVULSO | D22: CHIP_AVULSO | E22: -

Sheet PRODUTOS
A1: Cod_Sap | B1: Descricao_Sap | C1: Modelo (Nome DPGC) | D1: Cor | E1: Nome Comercial | F1: Fabricante | G1: Categoria | H1: Subcategoria | I1: ID_DPGC | J1: Tecnologia | K1: Produto com eSIM | L1: Gama | M1: Tabela | N1: Portfólio | O1: Lançamento | P1: Margem Conectados | Q1: Margem não conectados
A2: FFZT04663000 | B2: ZTE FWT WP755 (FIXO) PRETO BASICO | C2: FWT ZTE WP755 (Fixo) | D2: Preto | E2: FWT ZTE WP755 | F2: ZTE | G2: Box e Modem e FWT | H2: FWT | I2: ZTE102 | J2: 3G | K2: NÃO | L2: Low | M2: DEVICES ESPECIAIS | N2: EOL | O2: - | P2: 0% | Q2: 0%
A3: RGWN00162000 | B3: WNC ROTEADOR WLD71 PRETO LTE | C3: BLACKBOX WNC WLD71 (LTE 28) | D3: Preto | E3: BLACKBOX FLEX WLD71 (LTE 28) | F3: Flex | G3: Box e Modem e FWT | H3: Box e Modem | I3: FLX02 | J3: 4G | K3: NÃO | L3: Premium | M3: DEVICES ESPECIAIS | N3: EOL | O3: - | P3: 0.1 | Q3: 0%
A4: RGWN00262000 | B4: WNC ROTEADOR WLD71-T5A PRETO LTE | C4: BLACKBOX WNC WLD71 (LTE 28) | D4: Preto | E4: BLACKBOX FLEX WLD71 (LTE 28) | F4: Flex | G4: Box e Modem e FWT | H4: Box e Modem | I4: FLX02 | J4: 4G | K4: NÃO | L4: Premium | M4: DEVICES ESPECIAIS | N4: EOL | O4: - | P4: 0.1 | Q4: 0%
A5: BGSA34762000 | B5: SAMSUNG TAB A8 S PEN | C5: Samsung P205 | D5: Preto | E5: Galaxy TAB A 8'' Spen | F5: Samsung | G5: Notebook e Tablets | H5: Tablet | I5: SAM302 | J5: 4G | K5: NÃO | L5: Tablet | M5: TABLETS | N5: EOL | O5: - | P5: 0.15 | Q5: 0%
A6: AFML00762000 | B6: MULTILASER VITA 3G C/ BASE (FIXO) PRETO | C6: Multilaser P9109 | D6: Preto | E6: Multi Vita 3G | F6: Multi | G6: Box e Modem e FWT | H6: FWT | I6: MUL11 | J6: 3G | K6: NÃO | L6: Barra Câmera 3G | M6: DEVICES ESPECIAIS | N6: EOL | O6: - | P6: 0% | Q6: 0%
A7: MGHU05523000 | B7: HUAWEI MODEM E8372 BRANCO WIFI LTE | C7: Pen Modem Huawei E8372 (LTE WIFI) | D7: Branco | E7: Pen Modem Huawei E8372 (LTE Wi-Fi 28) | F7: Huawei | G7: Box e Modem e FWT | H7: Box e Modem | I7: HUA119 | J7: 4G | K7: NÃO | L7: Modem | M7: DEVICES ESPECIAIS | N7: EOL | O7: - | P7: 0% | Q7: 0%
A8: MGZT05123000 | B8: ZTE MF79S MODEM BRANCO | C8: Pen Modem ZTE MF79S | D8: Branco | E8: Pen Modem ZTE MF79S | F8: ZTE | G8: Box e Modem e FWT | H8: Box e Modem | I8: ZTE000006 | J8: 4G | K8: NÃO | L8: Modem | M8: DEVICES ESPECIAIS | N8: EOL | O8: - | P8: 0% | Q8: 0%
A9: TGSA35312007 | B9: SAMSUNG A505 128GB SMART AZ PPB/PI107/04 | C9: Samsung A505 128GB | D9: Azul | E9: Samsung Galaxy A50 128GB | F9: Samsung | G9: Smartphone | H9: Smartphone | I9: SAM316 | J9: 4G | K9: NÃO | L9: Premium | M9: SMARTPHONES | N9: EOL | O9: 43728 | P9: 0% | Q9: 0%
A10: TGSA35314007 | B10: SAMSUNG A505 128GB SMART AZ PPB/PI324/14 | C10: Samsung A505 128GB | D10: Azul | E10: Samsung Galaxy A50 128GB | F10: Samsung | G10: Smartphone | H10: Smartphone | I10: SAM316 | J10: 4G | K10: NÃO | L10: Premium | M10: SMARTPHONES | N10: EOL | O10: 43728 | P10: 0% | Q10: 0%
A11: DGAP10536000 | B11: APPLE WATCH S5 PSR SPORT 40MM DEMO DRDO | C11: Apple Watch S5 Pulseira Sport 40MM (Demo) | D11: Dourado | E11: Apple Watch S5 Pulseira Sport 40MM | F11: Apple | G11: Bem Estar | H11: Smartwatch | I11: APX96 | J11: 4G | K11: SIM | L11: Wearable Conectado | M11: ELETRÔNICOS | N11: EOL | O11: 43749 | P11: 0% | Q11: 0%
A12: TGSA35714000 | B12: SAMSUNG A207M SMART AZ PPB/PI324/14 | C12: Samsung A207G | D12: Azul | E12: Samsung Galaxy A20S | F12: Samsung | G12: Smartphone | H12: Smartphone | I12: SAM317 | J12: 4G | K12: NÃO | L12: Mid | M12: SMARTPHONES | N12: EOL | O12: 43798 | P12: 0% | Q12: 0%
A13: DGAP095R2000 | B13: APPLE IPHONE 11 256GB RX PPB/PI643/10 | C13: iPhone 11 256GB | D13: Roxo | E13: iPhone 11 256GB | F13: Apple | G13: Smartphone | H13: Smartphone | I13: APP79 | J13: 4G | K13: SIM | L13: Flagship | M13: SMARTPHONES | N13: EOL | O13: 43749 | P13: 0% | Q13: 0%
A14: DGAP11026000 | B14: APPLE IPHONE SE 64GB DEMO BR | C14: iPhone SE 64GB (Demo) | D14: Branco | E14: iPhone SE 64GB (Demo) | F14: Apple | G14: Smartphone | H14: Smartphone | I14: APX102 | J14: 4G | K14: SIM | L14: Flagship | M14: DEMO | N14: EOL | O14: - | P14: 0% | Q14: 0%
A15: DGAP11006000 | B15: APPLE IPHONE SE 64GB DEMO VM | C15: iPhone SE 64GB (Demo) | D15: Vermelho | E15: iPhone SE 64GB (Demo) | F15: Apple | G15: Smartphone | H15: Smartphone | I15: APX102 | J15: 4G | K15: SIM | L15: Flagship | M15: DEMO | N15: EOL | O15: - | P15: 0% | Q15: 0%
A16: TGSA37362000 | B16: SAMSUNG A115M SMART PT PPB/PI432/11 | C16: Samsung A115M | D16: Preto | E16: Samsung Galaxy A11 | F16: Samsung | G16: Smartphone | H16: Smartphone | I16: SAM331 | J16: 4G | K16: NÃO | L16: Mid | M16: SMARTPHONES | N16: EOL | O16: 43995 | P16: 0% | Q16: 0%
A17: TGSA37264000 | B17: SAMSUNG A217M SMART PT PPB/PI324/14 | C17: Samsung A217M | D17: Preto | E17: Samsung Galaxy A21S | F17: Samsung | G17: Smartphone | H17: Smartphone | I17: SAM332 | J17: 4G | K17: NÃO | L17: High | M17: SMARTPHONES | N17: EOL | O17: 43995 | P17: 0% | Q17: 0%
A18: BGSA35562000 | B18: SAMSUNG T295 TABLET PT PPB/PI432/11 | C18: Samsung Tab T295 | D18: Preto | E18: Samsung Galaxy Tab A 8" | F18: Samsung | G18: Notebook e Tablets | H18: Tablet | I18: SAM320 | J18: 4G | K18: NÃO | L18: Tablet | M18: TABLETS | N18: EOL | O18: - | P18: 0% | Q18: 0%
A19: MGZT05323000 | B19: ZTE MF79U MODEM BR | C19: ZTE MF79U MODEM | D19: Branco | E19: Pen Modem MF79U (LTE Wi-Fi 28) | F19: ZTE | G19: Box e Modem e FWT | H19: Box e Modem | I19: ZTE126 | J19: 4G | K19: NÃO | L19: Modem | M19: DEVICES ESPECIAIS | N19: EOL | O19: - | P19: 0.15 | Q19: 0%
A20: DGAP126G3000 | B20: APPLE IPHONE 12 256GB VD | C20: iPhone 12 256GB | D20: Verde | E20: iPhone 12 256GB | F20: Apple | G20: Smartphone | H20: Smartphone | I20: APP139 | J20: 5G | K20: SIM | L20: Flagship | M20: SMARTPHONES | N20: EOL | O20: 44148 | P20: 0% | Q20: 0%
A21: RGWN00462000 | B21: BLACKBOX BLUCASTLE BC-4GMCPGA LTE PT | C21: Blackbox Blucastle BC (4GLTE) | D21: Preto | E21: Blackbox Bluecastle | F21: Blucastle | G21: Box e Modem e FWT | H21: Box e Modem | I21: FLX04 | J21: 4G | K21: NÃO | L21: Premium | M21: DEVICES ESPECIAIS | N21: EOL | O21: - | P21: 0.1 | Q21: 0%
A22: BGSA38534007 | B22: SAMSUNG T505 TABLET DR PPB/PI291/12 | C22: Samsug T505 Tablet | D22: Dourado | E22: Samsung Galaxy Tab A7 10.4" 64GB | F22: Samsung | G22: Notebook e Tablets | H22: Tablet | I22: SAM357 | J22: 4G | K22: NÃO | L22: Tablet | M22: TABLETS | N22: EOL | O22: - | P22: 0.15 | Q22: 0%
A23: BGSA38534000 | B23: SAMSUNG T505 TABLET DR PPB/PI291/12 | C23: Samsug T505 Tablet | D23: Dourado | E23: Samsung Galaxy Tab A7 10.4" 64GB | F23: Samsung | G23: Notebook e Tablets | H23: Tablet | I23: SAM357 | J23: 4G | K23: NÃO | L23: Tablet | M23: TABLETS | N23: EOL | O23: - | P23: 0.15 | Q23: 0%
A24: AFML00763000 | B24: MULTILASER VITA 3G C/ BASE (FIXO) PRETO | C24: Multilaser P9109 | D24: Preto | E24: Multi Vita 3G | F24: Multi | G24: Box e Modem e FWT | H24: FWT | I24: MUL11 | J24: 3G | K24: NÃO | L24: Barra Câmera 3G | M24: DEVICES ESPECIAIS | N24: EOL | O24: - | P24: 0% | Q24: 0%
A25: MGZT05263000 | B25: ZTE MF971 MODEM PRETO | C25: Pen Modem ZTE MF971 | D25: Preto | E25: Pen Modem ZTE MF971 CA | F25: ZTE | G25: Box e Modem e FWT | H25: Box e Modem | I25: ZTE129 | J25: 4G | K25: NÃO | L25: Modem | M25: DEVICES ESPECIAIS | N25: EOL | O25: - | P25: 0% | Q25: 0%
A26: TGMO40182000 | B26: MOTOROLA XT2095 SMARTPHONE 64GB CB | C26: Motorola XT2095 | D26: Cobre | E26: Moto E7 64GB | F26: Motorola | G26: Smartphone | H26: Smartphone | I26: MOT144 | J26: 4G | K26: NÃO | L26: Mid | M26: SMARTPHONES | N26: EOL | O26: 44176 | P26: 0% | Q26: 0%
A27: TGSA39062007 | B27: SAMSUNG A025M SMART PT PPB/PI432/11 | C27: Samsung A025M | D27: Preto | E27: Samsung Galaxy A02S | F27: Samsung | G27: Smartphone | H27: Smartphone | I27: SAM367 | J27: 4G | K27: NÃO | L27: Mid | M27: SMARTPHONES | N27: EOL | O27: 44218 | P27: 0% | Q27: 0%
A28: TGSA39102000 | B28: SAMSUNG A125M SMART VM PPB/PI432/11 | C28: Samsung A125M | D28: Vermelho | E28: Samsung Galaxy A12 | F28: Samsung | G28: Smartphone | H28: Smartphone | I28: SAM366 | J28: 4G | K28: NÃO | L28: Mid | M28: SMARTPHONES | N28: EOL | O28: 44218 | P28: 0% | Q28: 0%
A29: DGAP13862007 | B29: APPLE IPHONE 11 256GB PT | C29: iPhone 11 256GB | D29: Preto | E29: iPhone 11 256GB | F29: Apple | G29: Smartphone | H29: Smartphone | I29: APP79 | J29: 4G | K29: SIM | L29: Flagship | M29: SMARTPHONES | N29: EOL | O29: 43749 | P29: 0% | Q29: 0%
A30: DGAP09326000 | B30: APPLE IPHONE 11 64GB DEMO BRANCO | C30: iPhone 11 64GB (Demo) | D30: Branco | E30: iPhone 11 64GB (Demo) | F30: Apple | G30: Smartphone | H30: Smartphone | I30: APX77 | J30: 4G | K30: SIM | L30: Flagship | M30: DEMO | N30: EOL | O30: - | P30: 0% | Q30: 0%
A31: DGAP09306000 | B31: APPLE IPHONE 11 64GB DEMO VERMELHO | C31: iPhone 11 64GB (Demo) | D31: Vermelho | E31: iPhone 11 64GB (Demo) | F31: Apple | G31: Smartphone | H31: Smartphone | I31: APX77 | J31: 4G | K31: SIM | L31: Flagship | M31: DEMO | N31: EOL | O31: - | P31: 0% | Q31: 0%
A32: DGAP093Y6000 | B32: APPLE IPHONE 11 64GB DEMO AMARELO | C32: iPhone 11 64GB (Demo) | D32: Amarelo | E32: iPhone 11 64GB (Demo) | F32: Apple | G32: Smartphone | H32: Smartphone | I32: APX77 | J32: 4G | K32: SIM | L32: Flagship | M32: DEMO | N32: EOL | O32: - | P32: 0% | Q32: 0%
A33: DGAP093R6000 | B33: APPLE IPHONE 11 64GB DEMO ROXO | C33: iPhone 11 64GB (Demo) | D33: Roxo | E33: iPhone 11 64GB (Demo) | F33: Apple | G33: Smartphone | H33: Smartphone | I33: APX77 | J33: 4G | K33: SIM | L33: Flagship | M33: DEMO | N33: EOL | O33: - | P33: 0% | Q33: 0%
A34: DGAP093G6000 | B34: APPLE IPHONE 11 64GB DEMO VERDE | C34: iPhone 11 64GB (Demo) | D34: Verde | E34: iPhone 11 64GB (Demo) | F34: Apple | G34: Smartphone | H34: Smartphone | I34: APX77 | J34: 4G | K34: SIM | L34: Flagship | M34: DEMO | N34: EOL | O34: - | P34: 0% | Q34: 0%
A35: DGAP09946000 | B35: APPLE IPHONE 11 PRO 64GB DEMO PRATA | C35: iPhone 11 Pro 64GB (Demo) | D35: Prata | E35: iPhone 11 Pro 64GB (Demo) | F35: Apple | G35: Smartphone | H35: Smartphone | I35: APX80 | J35: 4G | K35: SIM | L35: Flagship | M35: DEMO | N35: EOL | O35: - | P35: 0% | Q35: 0%
A36: DGAP09936000 | B36: APPLE IPHONE 11 PRO 64GB DEMO DOURADO | C36: iPhone 11 Pro 64GB (Demo) | D36: Dourado | E36: iPhone 11 Pro 64GB (Demo) | F36: Apple | G36: Smartphone | H36: Smartphone | I36: APX80 | J36: 4G | K36: SIM | L36: Flagship | M36: DEMO | N36: EOL | O36: - | P36: 0% | Q36: 0%
A37: DGAP099G6000 | B37: APPLE IPHONE 11 PRO 64GB DEMO VERDE | C37: iPhone 11 Pro 64GB (Demo) | D37: Verde | E37: iPhone 11 Pro 64GB (Demo) | F37: Apple | G37: Smartphone | H37: Smartphone | I37: APX80 | J37: 4G | K37: SIM | L37: Flagship | M37: DEMO | N37: EOL | O37: - | P37: 0% | Q37: 0%
A38: DGAP096C6000 | B38: APPLE IPHONE 11 PRO MAX 64GB DEMO CINZA | C38: iPhone 11 Pro Max 64GB (Demo) | D38: Cinza | E38: iPhone 11 Pro Max 64GB (Demo) | F38: Apple | G38: Smartphone | H38: Smartphone | I38: APX83 | J38: 4G | K38: SIM | L38: Flagship | M38: DEMO | N38: EOL | O38: - | P38: 0% | Q38: 0%
A39: DGAP09646000 | B39: APPLE IPHONE 11 PRO MAX 64GB DEMO PRATA | C39: iPhone 11 Pro Max 64GB (Demo) | D39: Prata | E39: iPhone 11 Pro Max 64GB (Demo) | F39: Apple | G39: Smartphone | H39: Smartphone | I39: APX83 | J39: 4G | K39: SIM | L39: Flagship | M39: DEMO | N39: EOL | O39: - | P39: 0% | Q39: 0%
A40: DGAP09636000 | B40: APPLE IPHONE 11 PRO MAX 64GB DEMO DOURADO | C40: iPhone 11 Pro Max 64GB (Demo) | D40: Dourado | E40: iPhone 11 Pro Max 64GB (Demo) | F40: Apple | G40: Smartphone | H40: Smartphone | I40: APX83 | J40: 4G | K40: SIM | L40: Flagship | M40: DEMO | N40: EOL | O40: - | P40: 0% | Q40: 0%
...

Sheet SMARTPHONES
E1: SMARTPHONES e WATCHES CONECTADOS | NS1: TABELA ANTERIOR
E2: Vigência a partir de: 15/09/2026 | F2: TABELA REGULAR | GW2: TABELA RENOVA | NS2: TABELA REGULAR | OC2: TABELA RENOVA | ON2: Δ | OO2: Δ Renova | OQ2: TABELA REGULAR - Itaú Black e Platinum (Master), Itaú Infinite e Signature (Visa), Caixa (CEF), Santander, Banco do Brasil Ourocard (Via, Elo e Master) Sicredi, Banrisul (Visa e Master) e Banco BRB somente em até 18x | OZ2: TABELA REGULAR - Demais Cartões | PI2: TABELA REGULAR - Itaú Black e Platinum (Master), Itaú Infinite e Signature (Visa), Caixa (CEF), Santander, Banco do Brasil Ourocard (Via, Elo e Master) Sicredi, Banrisul (Visa e Master) e Banco BRB somente em até 18x | PR2: TABELA RENOVA - Demais Cartões
A3: PORTFÓLIO | B3: CATEGORIA | C3: MARCA | D3: OFERTA DE COMUNICAÇÃO | E3: Nome Comercial | F3: PRÉ | G3: PIX e Vivo Pay | H3: 2x | I3: 3x | J3: 4x | K3: 5x | L3: 6x | M3: 7x | N3: 8x | O3: 9x | P3: 10x | Q3: 11x | R3: 12x | S3: 13x | T3: 14x | U3: 15x | V3: 16x | W3: 17x | X3: 18x | Y3: 19x | Z3: 20x | AA3: 21x | AB3: CONTROLE BTL | AC3: PIX e Vivo Pay | AD3: 2x | AE3: 3x | AF3: 4x | AG3: 5x | AH3: 6x | AI3: 7x | AJ3: 8x | AK3: 9x | AL3: 10x | AM3: 11x | AN3: 12x | AO3: 13x | AP3: 14x | AQ3: 15x | AR3: 16x | AS3: 17x | AT3: 18x | AU3: 19x | AV3: 20x | AW3: 21x | AX3: CONTROLE ENTRADA | AY3: PIX e Vivo Pay | AZ3: 2x | BA3: 3x | BB3: 4x | BC3: 5x | BD3: 6x | BE3: 7x | BF3: 8x | BG3: 9x | BH3: 10x | BI3: 11x | BJ3: 12x | BK3: 13x | BL3: 14x | BM3: 15x | BN3: 16x | BO3: 17x | BP3: 18x | BQ3: 19x | BR3: 20x | BS3: 21x | BT3: CONTROLE ALTO VALOR | BU3: PIX e Vivo Pay | BV3: 2x | BW3: 3x | BX3: 4x | BY3: 5x | BZ3: 6x | CA3: 7x | CB3: 8x | CC3: 9x | CD3: 10x | CE3: 11x | CF3: 12x | CG3: 13x | CH3: 14x | CI3: 15x | CJ3: 16x | CK3: 17x | CL3: 18x | CM3: 19x | CN3: 20x | CO3: 21x | CP3: PÓS INDIVIDUAL | CQ3: PIX e Vivo Pay | CR3: 2x | CS3: 3x | CT3: 4x | CU3: 5x | CV3: 6x | CW3: 7x | CX3: 8x | CY3: 9x | CZ3: 10x | DA3: 11x | DB3: 12x | DC3: 13x | DD3: 14x | DE3: 15x | DF3: 16x | DG3: 17x | DH3: 18x | DI3: 19x | DJ3: 20x | DK3: 21x | DL3: FAMILIA 2 | DM3: PIX e Vivo Pay | DN3: 2x | DO3: 3x | DP3: 4x | DQ3: 5x | DR3: 6x | DS3: 7x | DT3: 8x | DU3: 9x | DV3: 10x | DW3: 11x | DX3: 12x | DY3: 13x | DZ3: 14x | EA3: 15x | EB3: 16x | EC3: 17x | ED3: 18x | EE3: 19x | EF3: 20x | EG3: 21x | EH3: FAMILIA 3 | EI3: PIX e Vivo Pay | EJ3: 2x | EK3: 3x | EL3: 4x | EM3: 5x | EN3: 6x | EO3: 7x | EP3: 8x | EQ3: 9x | ER3: 10x | ES3: 11x | ET3: 12x | EU3: 13x | EV3: 14x | EW3: 15x | EX3: 16x | EY3: 17x | EZ3: 18x | FA3: 19x | FB3: 20x | FC3: 21x | FD3: FAMILIA 4/5 | FE3: PIX e Vivo Pay | FF3: 2x | FG3: 3x | FH3: 4x | FI3: 5x | FJ3: 6x | FK3: 7x | FL3: 8x | FM3: 9x | FN3: 10x | FO3: 11x | FP3: 12x | FQ3: 13x | FR3: 14x | FS3: 15x | FT3: 16x | FU3: 17x | FV3: 18x | FW3: 19x | FX3: 20x | FY3: 21x | FZ3: VIVO V | GA3: PIX e Vivo Pay | GB3: 2x | GC3: 3x | GD3: 4x | GE3: 5x | GF3: 6x | GG3: 7x | GH3: 8x | GI3: 9x | GJ3: 10x | GK3: 11x | GL3: 12x | GM3: 13x | GN3: 14x | GO3: 15x | GP3: 16x | GQ3: 17x | GR3: 18x | GS3: 19x | GT3: 20x | GU3: 21x | GW3: DESCONTO | GX3: CONTROLE BTL | GY3: PIX e Vivo Pay | GZ3: 2x | HA3: 3x | HB3: 4x | HC3: 5x | HD3: 6x | HE3: 7x | HF3: 8x | HG3: 9x | HH3: 10x | HI3: 11x | HJ3: 12x | HK3: 13x | HL3: 14x | HM3: 15x | HN3: 16x | HO3: 17x | HP3: 18x | HQ3: 19x | HR3: 20x | HS3: 21x | HT3: CONTROLE ENTRADA | HU3: PIX e Vivo Pay | HV3: 2x | HW3: 3x | HX3: 4x | HY3: 5x | HZ3: 6x | IA3: 7x | IB3: 8x | IC3: 9x | ID3: 10x | IE3: 11x | IF3: 12x | IG3: 13x | IH3: 14x | II3: 15x | IJ3: 16x | IK3: 17x | IL3: 18x | IM3: 19x | IN3: 20x | IO3: 21x | IP3: CONTROLE ALTO VALOR | IQ3: PIX e Vivo Pay | IR3: 2x | IS3: 3x | IT3: 4x | IU3: 5x | IV3: 6x | IW3: 7x | IX3: 8x | IY3: 9x | IZ3: 10x | JA3: 11x | JB3: 12x | JC3: 13x | JD3: 14x | JE3: 15x | JF3: 16x | JG3: 17x | JH3: 18x | JI3: 19x | JJ3: 20x | JK3: 21x | JL3: PÓS INDIVIDUAL | JM3: PIX e Vivo Pay | JN3: 2x | JO3: 3x | JP3: 4x | JQ3: 5x | JR3: 6x | JS3: 7x | JT3: 8x | JU3: 9x | JV3: 10x | JW3: 11x | JX3: 12x | JY3: 13x | JZ3: 14x | KA3: 15x | KB3: 16x | KC3: 17x | KD3: 18x | KE3: 19x | KF3: 20x | KG3: 21x | KH3: FAMILIA 2 | KI3: PIX e Vivo Pay | KJ3: 2x | KK3: 3x | KL3: 4x | KM3: 5x | KN3: 6x | KO3: 7x | KP3: 8x | KQ3: 9x | KR3: 10x | KS3: 11x | KT3: 12x | KU3: 13x | KV3: 14x | KW3: 15x | KX3: 16x | KY3: 17x | KZ3: 18x | LA3: 19x | LB3: 20x | LC3: 21x | LD3: FAMILIA 3 | LE3: PIX e Vivo Pay | LF3: 2x | LG3: 3x | LH3: 4x | LI3: 5x | LJ3: 6x | LK3: 7x | LL3: 8x | LM3: 9x | LN3: 10x | LO3: 11x | LP3: 12x | LQ3: 13x | LR3: 14x | LS3: 15x | LT3: 16x | LU3: 17x | LV3: 18x | LW3: 19x | LX3: 20x | LY3: 21x | LZ3: FAMILIA 4/5 | MA3: PIX e Vivo Pay | MB3: 2x | MC3: 3x | MD3: 4x | ME3: 5x | MF3: 6x | MG3: 7x | MH3: 8x | MI3: 9x | MJ3: 10x | MK3: 11x | ML3: 12x | MM3: 13x | MN3: 14x | MO3: 15x | MP3: 16x | MQ3: 17x | MR3: 18x | MS3: 19x | MT3: 20x | MU3: 21x | MV3: VIVO V | MW3: PIX e Vivo Pay | MX3: 2x | MY3: 3x | MZ3: 4x | NA3: 5x | NB3: 6x | NC3: 7x | ND3: 8x | NE3: 9x | NF3: 10x | NG3: 11x | NH3: 12x | NI3: 13x | NJ3: 14x | NK3: 15x | NL3: 16x | NM3: 17x | NN3: 18x | NO3: 19x | NP3: 20x | NQ3: 21x | NS3: PRÉ | NT3: CONTROLE BTL | NU3: CONTROLE ENTRADA | NV3: CONTROLE ALTO VALOR | NW3: PÓS INDIVIDUAL | NX3: FAMILIA 2 | NY3: FAMILIA 3 | NZ3: FAMILIA 4/5 | OA3: VIVO V | OC3: DESCONTO | OD3: CONTROLE BTL | OE3: CONTROLE ENTRADA | OF3: CONTROLE ALTO VALOR | OG3: PÓS INDIVIDUAL | OH3: FAMILIA 2 | OI3: FAMILIA 3 | OJ3: FAMILIA 4/5 | OK3: VIVO V | OL3: Δ | OM3: Δ Renova | ON3: 8 | OO3: 1 | OQ3: CONTROLE BTL | OR3: CONTROLE ENTRADA | OS3: CONTROLE ALTO VALOR | OT3: PÓS INDIVIDUAL | OU3: FAMILIA 2 | OV3: FAMILIA 3 | OW3: FAMILIA 4/5 | OX3: VIVO V | OZ3: CONTROLE BTL | PA3: CONTROLE ENTRADA | PB3: CONTROLE ALTO VALOR | PC3: PÓS INDIVIDUAL | PD3: FAMILIA 2 | PE3: FAMILIA 3 | PF3: FAMILIA 4/5 | PG3: VIVO V | PI3: CONTROLE BTL | PJ3: CONTROLE ENTRADA | PK3: CONTROLE ALTO VALOR | PL3: PÓS INDIVIDUAL | PM3: FAMILIA 2 | PN3: FAMILIA 3 | PO3: FAMILIA 4/5 | PP3: VIVO V | PR3: CONTROLE BTL | PS3: CONTROLE ENTRADA | PT3: CONTROLE ALTO VALOR | PU3: PÓS INDIVIDUAL | PV3: FAMILIA 2 | PW3: FAMILIA 3 | PX3: FAMILIA 4/5 | PY3: VIVO V
A4: EOL | B4: Smartphone | C4: Apple | D4: Vivo Total Família 3 | E4: iPhone SE 5G 128GB | F4: 3399 | G4: 3059.1 | H4: 3399 | I4: 3399 | J4: 3399 | K4: 3399 | L4: 3399 | M4: 3399 | N4: 3399 | O4: 3399 | P4: 3399 | Q4: 3399 | R4: 3399 | S4: 3662.25 | T4: 3681.55 | U4: 3700.91 | V4: 3720.35 | W4: 3739.84 | X4: 3759.4 | Y4: 3779.03 | Z4: 3798.73 | AA4: 3818.49 | AB4: 3399 | AC4: 3059.1 | AD4: 3399 | AE4: 3399 | AF4: 3399 | AG4: 3399 | AH4: 3399 | AI4: 3399 | AJ4: 3399 | AK4: 3399 | AL4: 3399 | AM4: 3399 | AN4: 3399 | AO4: 3662.25 | AP4: 3681.55 | AQ4: 3700.91 | AR4: 3720.35 | AS4: 3739.84 | AT4: 3759.4 | AU4: 3779.03 | AV4: 3798.73 | AW4: 3818.49 | AX4: 3399 | AY4: 3059.1 | AZ4: 3399 | BA4: 3399 | BB4: 3399 | BC4: 3399 | BD4: 3399 | BE4: 3399 | BF4: 3399 | BG4: 3399 | BH4: 3399 | BI4: 3399 | BJ4: 3399 | BK4: 3662.25 | BL4: 3681.55 | BM4: 3700.91 | BN4: 3720.35 | BO4: 3739.84 | BP4: 3759.4 | BQ4: 3779.03 | BR4: 3798.73 | BS4: 3818.49 | BT4: 3399 | BU4: 3059.1 | BV4: 3399 | BW4: 3399 | BX4: 3399 | BY4: 3399 | BZ4: 3399 | CA4: 3399 | CB4: 3399 | CC4: 3399 | CD4: 3399 | CE4: 3399 | CF4: 3399 | CG4: 3662.25 | CH4: 3681.55 | CI4: 3700.91 | CJ4: 3720.35 | CK4: 3739.84 | CL4: 3759.4 | CM4: 3779.03 | CN4: 3798.73 | CO4: 3818.49 | CP4: 2799 | CQ4: 2519.1 | CR4: 2799 | CS4: 2799 | CT4: 2799 | CU4: 2799 | CV4: 2799 | CW4: 2799 | CX4: 2799 | CY4: 2799 | CZ4: 2799 | DA4: 2799 | DB4: 2799 | DC4: 3015.78 | DD4: 3031.67 | DE4: 3047.62 | DF4: 3063.62 | DG4: 3079.68 | DH4: 3095.78 | DI4: 3111.95 | DJ4: 3128.17 | DK4: 3144.44 | DL4: 2399 | DM4: 2159.1 | DN4: 2399 | DO4: 2399 | DP4: 2399 | DQ4: 2399 | DR4: 2399 | DS4: 2399 | DT4: 2399 | DU4: 2399 | DV4: 2399 | DW4: 2399 | DX4: 2399 | DY4: 2584.8 | DZ4: 2598.42 | EA4: 2612.09 | EB4: 2625.8 | EC4: 2639.56 | ED4: 2653.37 | EE4: 2667.23 | EF4: 2681.13 | EG4: 2695.07 | EH4: 2399 | EI4: 2159.1 | EJ4: 2399 | EK4: 2399 | EL4: 2399 | EM4: 2399 | EN4: 2399 | EO4: 2399 | EP4: 2399 | EQ4: 2399 | ER4: 2399 | ES4: 2399 | ET4: 2399 | EU4: 2584.8 | EV4: 2598.42 | EW4: 2612.09 | EX4: 2625.8 | EY4: 2639.56 | EZ4: 2653.37 | FA4: 2667.23 | FB4: 2681.13 | FC4: 2695.07 | FD4: 2299 | FE4: 2069.1 | FF4: 2299 | FG4: 2299 | FH4: 2299 | FI4: 2299 | FJ4: 2299 | FK4: 2299 | FL4: 2299 | FM4: 2299 | FN4: 2299 | FO4: 2299 | FP4: 2299 | FQ4: 2477.06 | FR4: 2490.11 | FS4: 2503.21 | FT4: 2516.35 | FU4: 2529.54 | FV4: 2542.77 | FW4: 2556.04 | FX4: 2569.37 | FY4: 2582.73 | FZ4: 2099 | GA4: 1889.1 | GB4: 2099 | GC4: 2099 | GD4: 2099 | GE4: 2099 | GF4: 2099 | GG4: 2099 | GH4: 2099 | GI4: 2099 | GJ4: 2099 | GK4: 2099 | GL4: 2099 | GM4: 2261.57 | GN4: 2273.48 | GO4: 2285.44 | GP4: 2297.44 | GQ4: 2309.48 | GR4: 2321.56 | GS4: 2333.68 | GT4: 2345.85 | GU4: 2358.05 | GW4: 0 | GX4: 3399 | GY4: 3059.1 | GZ4: 3399 | HA4: 3399 | HB4: 3399 | HC4: 3399 | HD4: 3399 | HE4: 3399 | HF4: 3399 | HG4: 3399 | HH4: 3399 | HI4: 3399 | HJ4: 3399 | HK4: 3662.25 | HL4: 3681.55 | HM4: 3700.91 | HN4: 3720.35 | HO4: 3739.84 | HP4: 3759.4 | HQ4: 3779.03 | HR4: 3798.73 | HS4: 3818.49 | HT4: 3399 | HU4: 3059.1 | HV4: 3399 | HW4: 3399 | HX4: 3399 | HY4: 3399 | HZ4: 3399 | IA4: 3399 | IB4: 3399 | IC4: 3399 | ID4: 3399 | IE4: 3399 | IF4: 3399 | IG4: 3662.25 | IH4: 3681.55 | II4: 3700.91 | IJ4: 3720.35 | IK4: 3739.84 | IL4: 3759.4 | IM4: 3779.03 | IN4: 3798.73 | IO4: 3818.49 | IP4: 3399 | IQ4: 3059.1 | IR4: 3399 | IS4: 3399 | IT4: 3399 | IU4: 3399 | IV4: 3399 | IW4: 3399 | IX4: 3399 | IY4: 3399 | IZ4: 3399 | JA4: 3399 | JB4: 3399 | JC4: 3662.25 | JD4: 3681.55 | JE4: 3700.91 | JF4: 3720.35 | JG4: 3739.84 | JH4: 3759.4 | JI4: 3779.03 | JJ4: 3798.73 | JK4: 3818.49 | JL4: 2799 | JM4: 2519.1 | JN4: 2799 | JO4: 2799 | JP4: 2799 | JQ4: 2799 | JR4: 2799 | JS4: 2799 | JT4: 2799 | JU4: 2799 | JV4: 2799 | JW4: 2799 | JX4: 2799 | JY4: 3015.78 | JZ4: 3031.67 | KA4: 3047.62 | KB4: 3063.62 | KC4: 3079.68 | KD4: 3095.78 | KE4: 3111.95 | KF4: 3128.17 | KG4: 3144.44 | KH4: 2399 | KI4: 2159.1 | KJ4: 2399 | KK4: 2399 | KL4: 2399 | KM4: 2399 | KN4: 2399 | KO4: 2399 | KP4: 2399 | KQ4: 2399 | KR4: 2399 | KS4: 2399 | KT4: 2399 | KU4: 2584.8 | KV4: 2598.42 | KW4: 2612.09 | KX4: 2625.8 | KY4: 2639.56 | KZ4: 2653.37 | LA4: 2667.23 | LB4: 2681.13 | LC4: 2695.07 | LD4: 2399 | LE4: 2159.1 | LF4: 2399 | LG4: 2399 | LH4: 2399 | LI4: 2399 | LJ4: 2399 | LK4: 2399 | LL4: 2399 | LM4: 2399 | LN4: 2399 | LO4: 2399 | LP4: 2399 | LQ4: 2584.8 | LR4: 2598.42 | LS4: 2612.09 | LT4: 2625.8 | LU4: 2639.56 | LV4: 2653.37 | LW4: 2667.23 | LX4: 2681.13 | LY4: 2695.07 | LZ4: 2299 | MA4: 2069.1 | MB4: 2299 | MC4: 2299 | MD4: 2299 | ME4: 2299 | MF4: 2299 | MG4: 2299 | MH4: 2299 | MI4: 2299 | MJ4: 2299 | MK4: 2299 | ML4: 2299 | MM4: 2477.06 | MN4: 2490.11 | MO4: 2503.21 | MP4: 2516.35 | MQ4: 2529.54 | MR4: 2542.77 | MS4: 2556.04 | MT4: 2569.37 | MU4: 2582.73 | MV4: 2099 | MW4: 1889.1 | MX4: 2099 | MY4: 2099 | MZ4: 2099 | NA4: 2099 | NB4: 2099 | NC4: 2099 | ND4: 2099 | NE4: 2099 | NF4: 2099 | NG4: 2099 | NH4: 2099 | NI4: 2261.57 | NJ4: 2273.48 | NK4: 2285.44 | NL4: 2297.44 | NM4: 2309.48 | NN4: 2321.56 | NO4: 2333.68 | NP4: 2345.85 | NQ4: 2358.05 | NS4: 3399 | NT4: 3399 | NU4: 3399 | NV4: 3399 | NW4: 2799 | NX4: 2399 | NY4: 2399 | NZ4: 2299 | OA4: 2099 | OC4: 0 | OD4: 3399 | OE4: 3399 | OF4: 3399 | OG4: 2799 | OH4: 2399 | OI4: 2399 | OJ4: 2299 | OK4: 2099 | OL4: 0 | OM4: 0 | OQ4: 21x | OR4: 21x | OS4: 21x | OT4: 21x | OU4: 21x | OV4: 21x | OW4: 21x | OX4: 21x | OZ4: 12x | PA4: 12x | PB4: 12x | PC4: 12x | PD4: 12x | PE4: 12x | PF4: 12x | PG4: 12x | PI4: 21x | PJ4: 21x | PK4: 21x | PL4: 21x | PM4: 21x | PN4: 21x | PO4: 21x | PP4: 21x | PR4: 12x | PS4: 12x | PT4: 12x | PU4: 12x | PV4: 12x | PW4: 12x | PX4: 12x | PY4: 12x
A5: EOL | B5: Smartphone | C5: Apple | D5: Vivo Total Família 3 | E5: iPhone SE 5G 64GB | F5: 2899 | G5: 2609.1 | H5: 2899 | I5: 2899 | J5: 2899 | K5: 2899 | L5: 2899 | M5: 2899 | N5: 2899 | O5: 2899 | P5: 2899 | Q5: 2899 | R5: 2899 | S5: 3123.53 | T5: 3139.99 | U5: 3156.5 | V5: 3173.07 | W5: 3189.7 | X5: 3206.39 | Y5: 3223.13 | Z5: 3239.93 | AA5: 3256.78 | AB5: 2899 | AC5: 2609.1 | AD5: 2899 | AE5: 2899 | AF5: 2899 | AG5: 2899 | AH5: 2899 | AI5: 2899 | AJ5: 2899 | AK5: 2899 | AL5: 2899 | AM5: 2899 | AN5: 2899 | AO5: 3123.53 | AP5: 3139.99 | AQ5: 3156.5 | AR5: 3173.07 | AS5: 3189.7 | AT5: 3206.39 | AU5: 3223.13 | AV5: 3239.93 | AW5: 3256.78 | AX5: 2899 | AY5: 2609.1 | AZ5: 2899 | BA5: 2899 | BB5: 2899 | BC5: 2899 | BD5: 2899 | BE5: 2899 | BF5: 2899 | BG5: 2899 | BH5: 2899 | BI5: 2899 | BJ5: 2899 | BK5: 3123.53 | BL5: 3139.99 | BM5: 3156.5 | BN5: 3173.07 | BO5: 3189.7 | BP5: 3206.39 | BQ5: 3223.13 | BR5: 3239.93 | BS5: 3256.78 | BT5: 2849 | BU5: 2564.1 | BV5: 2849 | BW5: 2849 | BX5: 2849 | BY5: 2849 | BZ5: 2849 | CA5: 2849 | CB5: 2849 | CC5: 2849 | CD5: 2849 | CE5: 2849 | CF5: 2849 | CG5: 3069.65 | CH5: 3085.83 | CI5: 3102.06 | CJ5: 3118.35 | CK5: 3134.69 | CL5: 3151.09 | CM5: 3167.54 | CN5: 3184.05 | CO5: 3200.61 | CP5: 2299 | CQ5: 2069.1 | CR5: 2299 | CS5: 2299 | CT5: 2299 | CU5: 2299 | CV5: 2299 | CW5: 2299 | CX5: 2299 | CY5: 2299 | CZ5: 2299 | DA5: 2299 | DB5: 2299 | DC5: 2477.06 | DD5: 2490.11 | DE5: 2503.21 | DF5: 2516.35 | DG5: 2529.54 | DH5: 2542.77 | DI5: 2556.04 | DJ5: 2569.37 | DK5: 2582.73 | DL5: 1899 | DM5: 1709.1 | DN5: 1899 | DO5: 1899 | DP5: 1899 | DQ5: 1899 | DR5: 1899 | DS5: 1899 | DT5: 1899 | DU5: 1899 | DV5: 1899 | DW5: 1899 | DX5: 1899 | DY5: 2046.08 | DZ5: 2056.86 | EA5: 2067.68 | EB5: 2078.53 | EC5: 2089.43 | ED5: 2100.36 | EE5: 2111.32 | EF5: 2122.32 | EG5: 2133.36 | EH5: 1849 | EI5: 1664.1 | EJ5: 1849 | EK5: 1849 | EL5: 1849 | EM5: 1849 | EN5: 1849 | EO5: 1849 | EP5: 1849 | EQ5: 1849 | ER5: 1849 | ES5: 1849 | ET5: 1849 | EU5: 1992.2 | EV5: 2002.7 | EW5: 2013.24 | EX5: 2023.81 | EY5: 2034.41 | EZ5: 2045.05 | FA5: 2055.73 | FB5: 2066.44 | FC5: 2077.19 | FD5: 1799 | FE5: 1619.1 | FF5: 1799 | FG5: 1799 | FH5: 1799 | FI5: 1799 | FJ5: 1799 | FK5: 1799 | FL5: 1799 | FM5: 1799 | FN5: 1799 | FO5: 1799 | FP5: 1799 | FQ5: 1938.33 | FR5: 1948.55 | FS5: 1958.8 | FT5: 1969.08 | FU5: 1979.4 | FV5: 1989.75 | FW5: 2000.14 | FX5: 2010.56 | FY5: 2021.02 | FZ5: 1599 | GA5: 1439.1 | GB5: 1599 | GC5: 1599 | GD5: 1599 | GE5: 1599 | GF5: 1599 | GG5: 1599 | GH5: 1599 | GI5: 1599 | GJ5: 1599 | GK5: 1599 | GL5: 1599 | GM5: 1722.84 | GN5: 1731.92 | GO5: 1741.03 | GP5: 1750.17 | GQ5: 1759.34 | GR5: 1768.55 | GS5: 1777.78 | GT5: 1787.04 | GU5: 1796.34 | GW5: 0 | GX5: 2899 | GY5: 2609.1 | GZ5: 2899 | HA5: 2899 | HB5: 2899 | HC5: 2899 | HD5: 2899 | HE5: 2899 | HF5: 2899 | HG5: 2899 | HH5: 2899 | HI5: 2899 | HJ5: 2899 | HK5: 3123.53 | HL5: 3139.99 | HM5: 3156.5 | HN5: 3173.07 | HO5: 3189.7 | HP5: 3206.39 | HQ5: 3223.13 | HR5: 3239.93 | HS5: 3256.78 | HT5: 2899 | HU5: 2609.1 | HV5: 2899 | HW5: 2899 | HX5: 2899 | HY5: 2899 | HZ5: 2899 | IA5: 2899 | IB5: 2899 | IC5: 2899 | ID5: 2899 | IE5: 2899 | IF5: 2899 | IG5: 3123.53 | IH5: 3139.99 | II5: 3156.5 | IJ5: 3173.07 | IK5: 3189.7 | IL5: 3206.39 | IM5: 3223.13 | IN5: 3239.93 | IO5: 3256.78 | IP5: 2849 | IQ5: 2564.1 | IR5: 2849 | IS5: 2849 | IT5: 2849 | IU5: 2849 | IV5: 2849 | IW5: 2849 | IX5: 2849 | IY5: 2849 | IZ5: 2849 | JA5: 2849 | JB5: 2849 | JC5: 3069.65 | JD5: 3085.83 | JE5: 3102.06 | JF5: 3118.35 | JG5: 3134.69 | JH5: 3151.09 | JI5: 3167.54 | JJ5: 3184.05 | JK5: 3200.61 | JL5: 2299 | JM5: 2069.1 | JN5: 2299 | JO5: 2299 | JP5: 2299 | JQ5: 2299 | JR5: 2299 | JS5: 2299 | JT5: 2299 | JU5: 2299 | JV5: 2299 | JW5: 2299 | JX5: 2299 | JY5: 2477.06 | JZ5: 2490.11 | KA5: 2503.21 | KB5: 2516.35 | KC5: 2529.54 | KD5: 2542.77 | KE5: 2556.04 | KF5: 2569.37 | KG5: 2582.73 | KH5: 1899 | KI5: 1709.1 | KJ5: 1899 | KK5: 1899 | KL5: 1899 | KM5: 1899 | KN5: 1899 | KO5: 1899 | KP5: 1899 | KQ5: 1899 | KR5: 1899 | KS5: 1899 | KT5: 1899 | KU5: 2046.08 | KV5: 2056.86 | KW5: 2067.68 | KX5: 2078.53 | KY5: 2089.43 | KZ5: 2100.36 | LA5: 2111.32 | LB5: 2122.32 | LC5: 2133.36 | LD5: 1849 | LE5: 1664.1 | LF5: 1849 | LG5: 1849 | LH5: 1849 | LI5: 1849 | LJ5: 1849 | LK5: 1849 | LL5: 1849 | LM5: 1849 | LN5: 1849 | LO5: 1849 | LP5: 1849 | LQ5: 1992.2 | LR5: 2002.7 | LS5: 2013.24 | LT5: 2023.81 | LU5: 2034.41 | LV5: 2045.05 | LW5: 2055.73 | LX5: 2066.44 | LY5: 2077.19 | LZ5: 1799 | MA5: 1619.1 | MB5: 1799 | MC5: 1799 | MD5: 1799 | ME5: 1799 | MF5: 1799 | MG5: 1799 | MH5: 1799 | MI5: 1799 | MJ5: 1799 | MK5: 1799 | ML5: 1799 | MM5: 1938.33 | MN5: 1948.55 | MO5: 1958.8 | MP5: 1969.08 | MQ5: 1979.4 | MR5: 1989.75 | MS5: 2000.14 | MT5: 2010.56 | MU5: 2021.02 | MV5: 1599 | MW5: 1439.1 | MX5: 1599 | MY5: 1599 | MZ5: 1599 | NA5: 1599 | NB5: 1599 | NC5: 1599 | ND5: 1599 | NE5: 1599 | NF5: 1599 | NG5: 1599 | NH5: 1599 | NI5: 1722.84 | NJ5: 1731.92 | NK5: 1741.03 | NL5: 1750.17 | NM5: 1759.34 | NN5: 1768.55 | NO5: 1777.78 | NP5: 1787.04 | NQ5: 1796.34 | NS5: 2899 | NT5: 2899 | NU5: 2899 | NV5: 2849 | NW5: 2299 | NX5: 1899 | NY5: 1849 | NZ5: 1799 | OA5: 1599 | OC5: 0 | OD5: 2899 | OE5: 2899 | OF5: 2849 | OG5: 2299 | OH5: 1899 | OI5: 1849 | OJ5: 1799 | OK5: 1599 | OL5: 0 | OM5: 0 | OQ5: 21x | OR5: 21x | OS5: 21x | OT5: 21x | OU5: 21x | OV5: 21x | OW5: 21x | OX5: 21x | OZ5: 12x | PA5: 12x | PB5: 12x | PC5: 12x | PD5: 12x | PE5: 12x | PF5: 12x | PG5: 12x | PI5: 21x | PJ5: 21x | PK5: 21x | PL5: 21x | PM5: 21x | PN5: 21x | PO5: 21x | PP5: 21x | PR5: 12x | PS5: 12x | PT5: 12x | PU5: 12x | PV5: 12x | PW5: 12x | PX5: 12x | PY5: 12x
